package ch11;

public class ExceptionExam2 {

	public static void main(String[] args) {
		int[] arr1 = { 1, 2, 3, 4, 5 };
		int[] arr2 = { 1, 2, 3, 4, 5, 6, 7, 8, 9, 10 };
		int[] arr3 = null;

		try {
			printCheck(arr1);
			printCheck(arr2);
			printCheck(arr3);
			throw new ArrayLengthOver("asd");

		} catch (NullPointerException e) {
			System.out.println("배열의 길이가 50을 넘었습니다.");
		} catch(ArrayLengthOver e) {
			System.out.println(e.getMessage());
		}
		


	}

	// throw는 예외 발생시 호출을 한 주체로 떠넘긴다. 다만 main에서 throw를 하면 있으나 없으나 같다.
	public static boolean checkArr(int[] arr) throws NullPointerException {
		// 배열의 크기가 10보다 크거나 같으면 true를 반환, 그렇지 아니면 false를 반환
		if (arr.length >= 10) {
			return true;
		} else {
			return false;
		}
	}

	private static void printCheck(int[] arr) {
		if (checkArr(arr)) {
			System.out.println("배열의 길이가 10보다 크거나 같습니다.");
		} else {
			System.out.println("배열의 길이가 10보다 작습니다.");
		}
	}
}
